{"date":"Mon Mar 31 2025 16:28:06 GMT+0000 (Coordinated Universal Time)","error":{"code":"ERR_UNHANDLED_REJECTION"},"exception":true,"level":"error","message":"uncaughtException: This error originated either by throwing inside of an async function without a catch block, or by rejecting a promise which was not handled with .catch(). The promise rejected with the reason \"#<Object>\".\nUnhandledPromiseRejection: This error originated either by throwing inside of an async function without a catch block, or by rejecting a promise which was not handled with .catch(). The promise rejected with the reason \"#<Object>\".","os":{"loadavg":[5.18,2.51,1.06],"uptime":398.81},"process":{"argv":["/usr/local/bin/node","/app/src/server.ts"],"cwd":"/app","execPath":"/usr/local/bin/node","gid":0,"memoryUsage":{"arrayBuffers":19065512,"external":26017345,"heapTotal":107421696,"heapUsed":84069600,"rss":193773568},"pid":41,"uid":0,"version":"v18.20.8"},"stack":"UnhandledPromiseRejection: This error originated either by throwing inside of an async function without a catch block, or by rejecting a promise which was not handled with .catch(). The promise rejected with the reason \"#<Object>\".","trace":[]}
